<?xml version="1.0" encoding="utf-8"?>
<!-- =================================================================================== -->
<!-- |    This document was autogenerated by xacro from Pinna_bot.xacro                | -->
<!-- |    EDITING THIS FILE BY HAND IS NOT RECOMMENDED                                 | -->
<!-- =================================================================================== -->
<robot name="pinna_bot">
  <gazebo>
    <plugin filename="libgazebo_ros_control.so" name="gazebo_ros_control">
      <robotNamespace>/pinna_bot</robotNamespace>
      <robotSimType>gazebo_ros_control/DefaultRobotHWSim</robotSimType>
      <legacyModeNS>true</legacyModeNS>
    </plugin>
  </gazebo>
  <gazebo>
    <plugin filename="libgazebo_ros_diff_drive.so" name="differential_drive_controller">
      <legacyMode>false</legacyMode>
      <alwaysOn>true</alwaysOn>
      <updateRate>10</updateRate>
      <leftJoint>joint_wheel_left</leftJoint>
      <rightJoint>joint_wheel_right</rightJoint>
      <wheelSeparation>0.21</wheelSeparation>
      <wheelDiameter>0.115</wheelDiameter>
      <torque>0.018</torque>
      <commandTopic>cmd_vel</commandTopic>
      <odometryTopic>odom</odometryTopic>
      <odometryFrame>odom</odometryFrame>
      <robotBaseFrame>link_chasis</robotBaseFrame>
      <!-- base_footprint -->
    </plugin>
  </gazebo>
  <!--Physics constants-->
  <gazebo reference="link_wheel_right">
    <mu1>0.6</mu1>
    <mu2>0.6</mu2>
    <kp>500000.0</kp>
    <kd>10.0</kd>
    <minDepth>0.001</minDepth>
    <maxVel>0.1</maxVel>
    <fdir1>1 0 0</fdir1>
  </gazebo>
  <gazebo reference="link_wheel_left">
    <mu1>0.6</mu1>
    <mu2>0.6</mu2>
    <kp>500000.0</kp>
    <kd>10.0</kd>
    <minDepth>0.001</minDepth>
    <maxVel>0.1</maxVel>
    <fdir1>1 0 0</fdir1>
  </gazebo>
  <gazebo reference="link_caster_wheel">
    <mu1>0.3</mu1>
    <mu2>0.3</mu2>
    <kp>1000000.0</kp>
    <kd>100.0</kd>
    <minDepth>0.001</minDepth>
    <maxVel>1.0</maxVel>
  </gazebo>
  <!--Plugin IMU-->
  <gazebo reference="imu_link">
    <gravity>true</gravity>
    <sensor name="imu_sensor" type="imu">
      <always_on>true</always_on>
      <update_rate>100</update_rate>
      <visualize>true</visualize>
      <topic>imu_topic</topic>
      <plugin filename="libgazebo_ros_imu_sensor.so" name="imu_plugin">
        <topicName>pinna_bot/imu</topicName>
        <bodyName>imu_link</bodyName>
        <updateRateHZ>10.0</updateRateHZ>
        <gaussianNoise>0.0</gaussianNoise>
        <xyzOffset>0 0 0</xyzOffset>
        <rpyOffset>0 0 0</rpyOffset>
        <frameName>imu_link</frameName>
        <initialOrientationAsReference>true</initialOrientationAsReference>
        <!--false-->
      </plugin>
      <pose>0 0 0 0 0 0</pose>
    </sensor>
  </gazebo>
  <!--Plugin Camara-->
  <gazebo reference="camera_link">
    <sensor name="camara" type="camera">
      <update_rate>20.0</update_rate>
      <camera name="head">
        <horizontal_fov>1.3962634</horizontal_fov>
        <image>
          <width>1920</width>
          <height>1080</height>
          <format>R8G8B8</format>
        </image>
        <clip>
          <near>0.02</near>
          <far>300</far>
        </clip>
      </camera>
      <plugin filename="libgazebo_ros_camera.so" name="camera_controller">
        <alwaysOn>true</alwaysOn>
        <updateRate>0.0</updateRate>
        <cameraName>pinna_bot/camara</cameraName>
        <imageTopicName>image_raw</imageTopicName>
        <cameraInfoTopicName>camera_info</cameraInfoTopicName>
        <frameName>camera_link</frameName>
        <hackBaseline>0.07</hackBaseline>
        <distortionK1>0.0</distortionK1>
        <distortionK2>0.0</distortionK2>
        <distortionK3>0.0</distortionK3>
        <distortionT1>0.0</distortionT1>
        <distortionT2>0.0</distortionT2>
      </plugin>
    </sensor>
  </gazebo>
  <!--Plugin Lidar-->
  <gazebo reference="lidar_link">
    <sensor name="head_hokuyo_sensor" type="ray">
      <pose>0 0 0 0 0 0</pose>
      <visualize>false</visualize>
      <update_rate>20</update_rate>
      <ray>
        <scan>
          <horizontal>
            <samples>720</samples>
            <resolution>1</resolution>
            <min_angle>-3.14</min_angle>
            <max_angle>3.14</max_angle>
          </horizontal>
        </scan>
        <range>
          <min>0.10</min>
          <max>12.0</max>
          <resolution>0.01</resolution>
        </range>
        <noise>
          <type>gaussian</type>
          <mean>0.0</mean>
          <stddev>0.01</stddev>
        </noise>
      </ray>
      <plugin filename="libgazebo_ros_laser.so" name="gazebo_ros_head_hokuyo_controller">
        <topicName>pinna_bot/laser/scan</topicName>
        <frameName>lidar_link</frameName>
      </plugin>
    </sensor>
  </gazebo>
  <!--FRONT-->
  <gazebo reference="sonar_front_link">
    <sensor name="sonar" type="ray">
      <update_rate>10</update_rate>
      <visualize>false</visualize>
      <ray>
        <scan>
          <horizontal>
            <samples>5</samples>
            <resolution>1</resolution>
            <min_angle>-0.1</min_angle>
            <max_angle>0.1</max_angle>
          </horizontal>
          <vertical>
            <samples>5</samples>
            <resolution>1</resolution>
            <min_angle>-0.1</min_angle>
            <max_angle>0.1</max_angle>
          </vertical>
        </scan>
        <range>
          <min>0.03</min>
          <max>4.0</max>
          <resolution>0.01</resolution>
        </range>
      </ray>
      <plugin filename="libgazebo_ros_range.so" name="gazebo_ros_range">
        <gaussianNoise>0.005</gaussianNoise>
        <alwaysOn>true</alwaysOn>
        <updateRate>10</updateRate>
        <topicName>pinna_bot/sonar/1</topicName>
        <frameName>sonar_front_link</frameName>
        <fov>0.5</fov>
        <radiation>ultrasound</radiation>
      </plugin>
    </sensor>
  </gazebo>
  <!--LEFT-->
  <gazebo reference="sonar_left_link">
    <sensor name="sonar" type="ray">
      <update_rate>10</update_rate>
      <visualize>false</visualize>
      <ray>
        <scan>
          <horizontal>
            <samples>5</samples>
            <resolution>1</resolution>
            <min_angle>-0.1</min_angle>
            <max_angle>0.1</max_angle>
          </horizontal>
          <vertical>
            <samples>5</samples>
            <resolution>1</resolution>
            <min_angle>-0.1</min_angle>
            <max_angle>0.1</max_angle>
          </vertical>
        </scan>
        <range>
          <min>0.055</min>
          <max>4.0</max>
          <resolution>0.01</resolution>
        </range>
      </ray>
      <plugin filename="libgazebo_ros_range.so" name="gazebo_ros_range">
        <gaussianNoise>0.005</gaussianNoise>
        <alwaysOn>true</alwaysOn>
        <updateRate>10</updateRate>
        <topicName>pinna_bot/sonar/2</topicName>
        <frameName>sonar_left_link</frameName>
        <fov>0.5</fov>
        <radiation>ultrasound</radiation>
      </plugin>
    </sensor>
  </gazebo>
  <!--RIGHT-->
  <gazebo reference="sonar_right_link">
    <sensor name="sonar" type="ray">
      <update_rate>10</update_rate>
      <visualize>false</visualize>
      <ray>
        <scan>
          <horizontal>
            <samples>5</samples>
            <resolution>1</resolution>
            <min_angle>-0.1</min_angle>
            <max_angle>0.1</max_angle>
          </horizontal>
          <vertical>
            <samples>5</samples>
            <resolution>1</resolution>
            <min_angle>-0.1</min_angle>
            <max_angle>0.1</max_angle>
          </vertical>
        </scan>
        <range>
          <min>0.055</min>
          <max>4.0</max>
          <resolution>0.01</resolution>
        </range>
      </ray>
      <plugin filename="libgazebo_ros_range.so" name="gazebo_ros_range">
        <gaussianNoise>0.005</gaussianNoise>
        <alwaysOn>true</alwaysOn>
        <updateRate>10</updateRate>
        <topicName>pinna_bot/sonar/3</topicName>
        <frameName>sonar_right_link</frameName>
        <fov>0.5</fov>
        <radiation>ultrasound</radiation>
      </plugin>
    </sensor>
  </gazebo>
  <material name="black">
    <color rgba="0.0 0.0 0.0 1.0"/>
  </material>
  <material name="blue">
    <color rgba="0.0 0.0 0.8 1.0"/>
  </material>
  <material name="green">
    <color rgba="0.0 0.8 0.0 1.0"/>
  </material>
  <material name="grey">
    <color rgba="0.2 0.2 0.2 1.0"/>
  </material>
  <material name="orange">
    <color rgba="1.0 0.423529411765 0.0392156862745 1.0"/>
  </material>
  <material name="brown">
    <color rgba="0.870588235294 0.811764705882 0.764705882353 1.0"/>
  </material>
  <material name="red">
    <color rgba="0.8 0.0 0.0 1.0"/>
  </material>
  <material name="white">
    <color rgba="1.0 1.0 1.0 1.0"/>
  </material>
  <!--Links o partes Chasis-->
  <link name="link_chassis">
    <!-- pose and inertial -->
    <pose>0 0 0.1 0 0 0</pose>
    <inertial>
      <mass value="3.0"/>
      <origin rpy="0 0 0" xyz="0 0 0"/>
      <inertia ixx="0.0655" ixy="0" ixz="0" iyy="0.0517" iyz="0" izz="0.14"/>
    </inertial>
    <!--Chasis -->
    <collision name="collision_chassis">
      <origin rpy="0 0 0" xyz="0 0 0.085"/>
      <geometry>
        <box size="0.22 0.320 0.173"/>
      </geometry>
    </collision>
    <visual>
      <origin rpy="0 0 0" xyz="0 0.160 0"/>
      <geometry>
        <mesh filename="package://pinnabot_description/meshes/Chasis_pinna_bot.dae"/>
      </geometry>
    </visual>
  </link>
  <!--Links caster-->
  <link name="link_caster_wheel">
    <inertial>
      <mass value="0.15"/>
      <inertia ixx="0.001107" ixy="0" ixz="0" iyy="0.001107" iyz="0" izz="0.002152"/>
    </inertial>
    <collision>
      <origin rpy="0 1.57 0" xyz="0 0.00 0.0"/>
      <geometry>
        <cylinder length="0.019" radius="0.020"/>
      </geometry>
    </collision>
    <visual>
      <origin rpy="0 0 0" xyz="0 0.021 0.035"/>
      <geometry>
        <mesh filename="package://pinnabot_description/meshes/caster_wheel.dae"/>
      </geometry>
    </visual>
  </link>
  <link name="link_caster_axis_support">
    <inertial>
      <mass value="0.08"/>
      <inertia ixx="1e-6" ixy="0" ixz="0" iyy="1e-6" iyz="0" izz="1e-6"/>
    </inertial>
    <collision>
      <origin rpy="0 0 0" xyz="0 -0.003 -0.02"/>
      <geometry>
        <box size="0.025 0.040 0.035"/>
      </geometry>
    </collision>
    <visual>
      <origin rpy="0 0 0" xyz="0 0 0"/>
      <geometry>
        <mesh filename="package://pinnabot_description/meshes/caster_axis_support.dae"/>
      </geometry>
    </visual>
  </link>
  <link name="link_caster_base">
    <inertial>
      <mass value="0.05"/>
      <inertia ixx="1e-6" ixy="0" ixz="0" iyy="1e-6" iyz="0" izz="1e-6"/>
    </inertial>
    <collision>
      <origin rpy="0 0 0" xyz="0 0 -0.0015"/>
      <geometry>
        <box size="0.045 0.045 0.003"/>
      </geometry>
    </collision>
    <visual>
      <origin rpy="0 0 0" xyz="0 0 0"/>
      <geometry>
        <mesh filename="package://pinnabot_description/meshes/caster_base.dae"/>
      </geometry>
    </visual>
  </link>
  <!--Links Wheels-->
  <link name="link_wheel_right">
    <inertial>
      <mass value="1.0"/>
      <origin rpy="0 1.5707 0" xyz="0 0 0"/>
      <inertia ixx="0.01107" ixy="0" ixz="0" iyy="0.01107" iyz="0" izz="0.02152"/>
    </inertial>
    <collision name="link_wheel_right_collision">
      <origin rpy="0 1.5707 0" xyz="0 0 0"/>
      <geometry>
        <cylinder length="0.022" radius="0.043"/>
      </geometry>
    </collision>
    <visual name="link_wheel_right_visual">
      <origin rpy="0 1.5707 0" xyz="0 0 0"/>
      <geometry>
        <mesh filename="package://pinnabot_description/meshes/Wheel_pinna_bot.dae"/>
      </geometry>
    </visual>
  </link>
  <link name="link_wheel_left">
    <inertial>
      <mass value="1.0"/>
      <origin rpy="0 -1.5707 0" xyz="0 0 0"/>
      <inertia ixx="0.01107" ixy="0" ixz="0" iyy="0.01107" iyz="0" izz="0.02152"/>
    </inertial>
    <collision name="link_wheel_left_collision">
      <origin rpy="0 -1.5707 0" xyz="0 0 0"/>
      <geometry>
        <cylinder length="0.022" radius="0.043"/>
      </geometry>
    </collision>
    <visual name="link_wheel_left_visual">
      <origin rpy="0 -1.5707 0" xyz="0 0 0"/>
      <geometry>
        <mesh filename="package://pinnabot_description/meshes/Wheel_pinna_bot.dae"/>
      </geometry>
    </visual>
  </link>
  <!-- imu -->
  <link name="imu_link">
    </link>
  <!-- Camera -->
  <link name="camera_link">
    <collision>
      <origin rpy="1.57 0 -1.57" xyz="0 0 0"/>
      <geometry>
        <box size="0.090 0.040  0.020"/>
      </geometry>
    </collision>
    <inertial>
      <mass value="0.160"/>
      <origin rpy="0 0 0" xyz="0 0 0"/>
      <inertia ixx="1e-6" ixy="0" ixz="0" iyy="1e-6" iyz="0" izz="1e-6"/>
    </inertial>
    <visual>
      <origin rpy="1.57 0 -1.57" xyz="0.1025 0.005 0"/>
      <geometry>
        <mesh filename="package://pinnabot_description/meshes/Camera_Logitech_C920Arm.dae"/>
      </geometry>
    </visual>
  </link>
  <!-- Module-Jetson -->
  <link name="module_jetson_link">
    <inertial>
      <mass value="0.4"/>
      <inertia ixx="0.0" ixy="0.0" ixz="0.0" iyy="0.0" iyz="0.0" izz="0.0"/>
    </inertial>
    <visual>
      <origin rpy="0.0 0.0 0.0" xyz="0.0 0.0 0.0"/>
      <geometry>
        <mesh filename="package://pinnabot_description/meshes/module_jetson.dae"/>
      </geometry>
    </visual>
  </link>
  <!-- Lidar -->
  <link name="lidar_link">
    <collision>
      <origin rpy="0 0 0" xyz="0 0 0"/>
      <geometry>
        <cylinder length="0.07" radius="0.05"/>
      </geometry>
    </collision>
    <visual>
      <origin rpy="0 0 -3.14" xyz="0 0 0"/>
      <geometry>
        <mesh filename="package://pinnabot_description/meshes/RPLidar.dae"/>
      </geometry>
    </visual>
    <inertial>
      <mass value="0.170"/>
      <origin rpy="0 0 0" xyz="0 0 0"/>
      <inertia ixx="1e-6" ixy="0" ixz="0" iyy="1e-6" iyz="0" izz="1e-6"/>
    </inertial>
  </link>
  <!-- Sonars o Ultrasonidos -->
  <link name="sonar_front_link">
    <inertial>
      <mass value="0.001"/>
      <origin rpy="0 0 0" xyz="0 0 0"/>
      <inertia ixx="0.000000017" ixy="0" ixz="0" iyy="0.000000017" iyz="0" izz="0.000000017"/>
    </inertial>
    <visual>
      <origin rpy="0 0 -1.5707" xyz="0 0 0"/>
      <geometry>
        <mesh filename="package://pinnabot_description/meshes/Ultrasonido.dae"/>
      </geometry>
    </visual>
  </link>
  <link name="sonar_left_link">
    <inertial>
      <mass value="0.001"/>
      <origin rpy="0 0 0" xyz="0 0 0"/>
      <inertia ixx="0.000000017" ixy="0" ixz="0" iyy="0.000000017" iyz="0" izz="0.000000017"/>
    </inertial>
    <visual>
      <origin rpy="0 0 -1.5707" xyz="0 0 0"/>
      <geometry>
        <mesh filename="package://pinnabot_description/meshes/Ultrasonido.dae"/>
      </geometry>
    </visual>
  </link>
  <link name="sonar_right_link">
    <inertial>
      <mass value="0.001"/>
      <origin rpy="0 0 0" xyz="0 0 0"/>
      <inertia ixx="0.000000017" ixy="0" ixz="0" iyy="0.000000017" iyz="0" izz="0.000000017"/>
    </inertial>
    <visual>
      <origin rpy="0 0 -1.5707" xyz="0 0 0"/>
      <geometry>
        <mesh filename="package://pinnabot_description/meshes/Ultrasonido.dae"/>
      </geometry>
    </visual>
  </link>
  <!--Joints o uniones-->
  <joint name="joint_caster" type="fixed">
    <origin rpy="0 0 0" xyz="0 -0.1105 0.03"/>
    <parent link="link_chassis"/>
    <child link="link_caster_base"/>
  </joint>
  <joint name="joint_caster1" type="continuous">
    <origin rpy="0 0 0" xyz="0 -0.018 -0.03"/>
    <parent link="link_caster_axis_support"/>
    <child link="link_caster_wheel"/>
    <axis rpy="0 0 0" xyz="1 0 0"/>
    <limit effort="10000" velocity="1000"/>
    <joint_properties damping="0.80" friction="1.0"/>
  </joint>
  <joint name="joint_caster2" type="continuous">
    <origin rpy="0 0 0" xyz="0 0 0"/>
    <parent link="link_caster_base"/>
    <child link="link_caster_axis_support"/>
    <axis rpy="0 0 0" xyz="0 0 1"/>
    <limit effort="10000" velocity="1000"/>
    <joint_properties damping="0.80" friction="1.0"/>
  </joint>
  <joint name="joint_wheel_right" type="continuous">
    <origin rpy="0 0 0" xyz="0.122 0.085 0.023"/>
    <child link="link_wheel_right"/>
    <parent link="link_chassis"/>
    <axis rpy="0 0 0" xyz="-1 0 0"/>
    <limit effort="10000" velocity="1000"/>
    <joint_properties damping="0.80" friction="1.0"/>
  </joint>
  <joint name="joint_wheel_left" type="continuous">
    <origin rpy="0 0 0" xyz="-0.122 0.085 0.023"/>
    <child link="link_wheel_left"/>
    <parent link="link_chassis"/>
    <axis rpy="0 0 0" xyz="-1 0 0"/>
    <limit effort="10000" velocity="1000"/>
    <joint_properties damping="0.80" friction="1.0"/>
  </joint>
  <joint name="joint_imu" type="fixed">
    <origin rpy="0 0 0" xyz="0 0.085 0.02"/>
    <child link="imu_link"/>
    <parent link="link_chassis"/>
  </joint>
  <joint name="joint_camera" type="fixed">
    <origin rpy="0 0 1.57" xyz="0 0.155 0.130"/>
    <parent link="link_chassis"/>
    <child link="camera_link"/>
  </joint>
  <joint name="joint_module_jetson" type="fixed">
    <origin rpy="0.0 0.0 0.0" xyz="0.0 0.0735 0.13"/>
    <parent link="link_chassis"/>
    <child link="module_jetson_link"/>
  </joint>
  <joint name="joint_lidar" type="fixed">
    <origin rpy="0 0 1.5707" xyz="0 0.075 0.190"/>
    <parent link="link_chassis"/>
    <child link="lidar_link"/>
  </joint>
  <joint name="joint_sonar_front" type="fixed">
    <origin rpy="0 0 1.5707" xyz="0 0.158 0.051"/>
    <parent link="link_chassis"/>
    <child link="sonar_front_link"/>
  </joint>
  <joint name="joint_sonar_left" type="fixed">
    <origin rpy="0 0 2.1" xyz="-0.08 0.1405 0.051"/>
    <parent link="link_chassis"/>
    <child link="sonar_left_link"/>
  </joint>
  <joint name="joint_sonar_right" type="fixed">
    <origin rpy="0 0 1.04" xyz="0.08 0.1405 0.051"/>
    <parent link="link_chassis"/>
    <child link="sonar_right_link"/>
  </joint>
  <!--Transmission -->
  <transmission name="trans1">
    <type>transmission_interface/SimpleTransmission</type>
    <joint name="joint_wheel_right">
      <hardwareInterface>hardware_interface/VelocityJointInterface</hardwareInterface>
    </joint>
    <actuator name="motor1">
      <!--<hardwareInterface>hardware_interface/VelocityJointInterface</hardwareInterface>-->
      <mechanicalReduction>1</mechanicalReduction>
    </actuator>
  </transmission>
  <transmission name="trans2">
    <type>transmission_interface/SimpleTransmission</type>
    <joint name="joint_wheel_left">
      <hardwareInterface>hardware_interface/VelocityJointInterface</hardwareInterface>
    </joint>
    <actuator name="motor2">
      <!--<hardwareInterface>hardware_interface/VelocityJointInterface</hardwareInterface>-->
      <mechanicalReduction>1</mechanicalReduction>
    </actuator>
  </transmission>
</robot>

