<?xml version='1.0'?>
<robot name="pinna_bot" xmlns:xacro="http://www.ros.org/wiki/xacro">  

  <!--incluyo el archivo de los plugins de Gazebo-->
  <xacro:include filename="$(find pinnabot_description)/urdf/Pinna_bot.gazebo" />
  <xacro:include filename="$(find pinnabot_description)/urdf/materials.xacro" />
  <xacro:include filename="$(find pinnabot_description)/urdf/macros.xacro" />

  
    
  <!--Links o partes Chasis-->
    <link name="link_chassis">

        <!-- pose and inertial -->
        <pose>0 0 0.1 0 0 0</pose>
        <inertial>
            <mass value="3.0"/>
            <origin rpy="0 0 0" xyz="0 0 0"/>
            <inertia ixx="0.0655" ixy="0" ixz="0" iyy="0.0517" iyz="0" izz="0.14"/>
        </inertial>

        <!--Chasis -->
        <collision name="collision_chassis">
            <origin rpy="0 0 0" xyz="0 0 0.085"/>
            <geometry>
                <box size="0.22 0.320 0.173"/>
            </geometry>
        </collision>

        <visual>
            <origin rpy="0 0 0" xyz="0 0.160 0"/>
            <geometry>
                <mesh filename="package://pinnabot_description/meshes/Chasis_pinna_bot.dae"/>
            </geometry>
        </visual>

    </link>


    <!--Links caster-->
    <link name="link_caster_wheel">
        <inertial>
            <mass value="0.15"/>            
            <inertia ixx="0.001107" ixy="0" ixz="0" iyy="0.001107" iyz="0" izz="0.002152"/>
        </inertial>
        <collision>
          <origin rpy="0 1.57 0" xyz="0 0.00 0.0"/>
          <geometry>
            <cylinder length="0.019" radius="0.020"/>
          </geometry>
        </collision>
        <visual>
          <origin xyz="0 0.021 0.035" rpy="0 0 0" />
          <geometry>
            <mesh filename="package://pinnabot_description/meshes/caster_wheel.dae"/>
          </geometry>
        </visual>
    </link>  

    <link name="link_caster_axis_support">
        <inertial>
            <mass value="0.08"/> 
            <inertia ixx="1e-6" ixy="0" ixz="0" iyy="1e-6" iyz="0" izz="1e-6" />           
        </inertial>
        <collision>
          <origin xyz="0 -0.003 -0.02" rpy="0 0 0" />
          <geometry>
            <box size="0.025 0.040 0.035"/>
          </geometry>
        </collision>
        <visual>
          <origin xyz="0 0 0" rpy="0 0 0" />
          <geometry>
            <mesh filename="package://pinnabot_description/meshes/caster_axis_support.dae"/>
          </geometry>
        </visual>
    </link>

    <link name="link_caster_base">
        <inertial>
            <mass value="0.05"/> 
            <inertia ixx="1e-6" ixy="0" ixz="0" iyy="1e-6" iyz="0" izz="1e-6" />           
        </inertial>
        <collision>
          <origin xyz="0 0 -0.0015" rpy="0 0 0" />
          <geometry>
            <box size="0.045 0.045 0.003"/>
          </geometry>
        </collision>
        <visual>
          <origin xyz="0 0 0" rpy="0 0 0" />
          <geometry>
            <mesh filename="package://pinnabot_description/meshes/caster_base.dae"/>
          </geometry>
        </visual>
    </link>



    <!--Links Wheels-->
    <link name="link_wheel_right">

        <inertial>
            <mass value="1.0"/>
            <origin rpy="0 1.5707 0" xyz="0 0 0"/>            
            <inertia ixx="0.01107" ixy="0" ixz="0" iyy="0.01107" iyz="0" izz="0.02152"/>
        </inertial>

        <collision name="link_wheel_right_collision">
            <origin rpy="0 1.5707 0" xyz="0 0 0"/>
            <geometry>
                <cylinder length="0.022" radius="0.043"/>
            </geometry>
        </collision>

        <visual name="link_wheel_right_visual">
            <origin rpy="0 1.5707 0" xyz="0 0 0"/>
            <geometry>
                <mesh filename="package://pinnabot_description/meshes/Wheel_pinna_bot.dae"/>
            </geometry>
        </visual>

    </link>
  
    <link name="link_wheel_left">

        <inertial>
            <mass value="1.0"/>
            <origin rpy="0 -1.5707 0" xyz="0 0 0"/>
            <inertia ixx="0.01107" ixy="0" ixz="0" iyy="0.01107" iyz="0" izz="0.02152"/>
        </inertial>

        <collision name="link_wheel_left_collision">
            <origin rpy="0 -1.5707 0" xyz="0 0 0"/>
            <geometry>
                <cylinder length="0.022" radius="0.043"/>
            </geometry>
        </collision>

        <visual name="link_wheel_left_visual">
            <origin rpy="0 -1.5707 0" xyz="0 0 0"/>
            <geometry>
                <mesh filename="package://pinnabot_description/meshes/Wheel_pinna_bot.dae"/>
            </geometry>
        </visual>

    </link>
    
    <!-- imu -->
    <link name="imu_link">
    </link>

    <!-- Camera -->
    <link name="camera_link">

      <collision>
        <origin xyz="0 0 0" rpy="1.57 0 -1.57"/>
        <geometry>
          <box size="0.090 0.040  0.020"/>
        </geometry>
      </collision>

      <inertial>
        <mass value="0.160" />
        <origin xyz="0 0 0" rpy="0 0 0"/>
        <inertia ixx="1e-6" ixy="0" ixz="0" iyy="1e-6" iyz="0" izz="1e-6" />
      </inertial>

      <visual>
        <origin xyz="0.1025 0.005 0" rpy="1.57 0 -1.57"/>
        <geometry>
          <mesh filename="package://pinnabot_description/meshes/Camera_Logitech_C920Arm.dae"/>
        </geometry>
      </visual>
    </link>

    <!-- Module-Jetson -->
    <link name="module_jetson_link">
      <inertial>
        <mass value="0.4"/>
        <inertia ixx="0.0" ixy="0.0" ixz="0.0" iyy="0.0" iyz="0.0" izz="0.0"/>
      </inertial>
      <visual>
        <origin xyz="0.0 0.0 0.0" rpy="0.0 0.0 0.0"/>
        <geometry>
          <mesh filename="package://pinnabot_description/meshes/module_jetson.dae"/>
        </geometry>
      </visual>
    </link>

    <!-- Lidar -->
    <link name="lidar_link">

        <collision>
          <origin xyz="0 0 0" rpy="0 0 0"/>
          <geometry>
            <cylinder length="0.07" radius="0.05"/>
          </geometry>
        </collision>

        <visual>
          <origin xyz="0 0 0" rpy="0 0 -3.14"/>
          <geometry>
            <mesh filename="package://pinnabot_description/meshes/RPLidar.dae"/>
          </geometry>
        </visual>

        <inertial>
          <mass value="0.170" />
          <origin xyz="0 0 0" rpy="0 0 0"/>
          <inertia ixx="1e-6" ixy="0" ixz="0" iyy="1e-6" iyz="0" izz="1e-6" />
        </inertial>

    </link>

    <!-- Sonars o Ultrasonidos -->
    <link name="sonar_front_link">

      <inertial>
        <mass value="0.001" />
        <origin xyz="0 0 0" rpy="0 0 0" />
        <inertia ixx="0.000000017" ixy="0" ixz="0" iyy="0.000000017" iyz="0" izz="0.000000017" />
      </inertial>

      <visual>
        <origin xyz="0 0 0" rpy="0 0 -1.5707" />
        <geometry>
          <mesh filename="package://pinnabot_description/meshes/Ultrasonido.dae"/>
        </geometry>
      </visual>
      
    </link>

    <link name="sonar_left_link">

      <inertial>
        <mass value="0.001" />
        <origin xyz="0 0 0" rpy="0 0 0" />
        <inertia ixx="0.000000017" ixy="0" ixz="0" iyy="0.000000017" iyz="0" izz="0.000000017" />
      </inertial>
      
      <visual>
        <origin xyz="0 0 0" rpy="0 0 -1.5707" />
        <geometry>
          <mesh filename="package://pinnabot_description/meshes/Ultrasonido.dae"/>
        </geometry>
      </visual>
      
    </link>
    
    <link name="sonar_right_link">

      <inertial>
        <mass value="0.001" />
        <origin xyz="0 0 0" rpy="0 0 0" />
        <inertia ixx="0.000000017" ixy="0" ixz="0" iyy="0.000000017" iyz="0" izz="0.000000017" />
      </inertial>
      
      <visual>
        <origin xyz="0 0 0" rpy="0 0 -1.5707" />
        <geometry>
          <mesh filename="package://pinnabot_description/meshes/Ultrasonido.dae"/>
        </geometry>
      </visual>
      
    </link>
    


 <!--Joints o uniones-->
    <joint name="joint_caster" type="fixed">
          <origin xyz="0 -0.1105 0.03" rpy="0 0 0"/>
          <parent link="link_chassis" />
          <child link="link_caster_base" />
    </joint>

    <joint name="joint_caster1" type="continuous">
          <origin xyz="0 -0.018 -0.03" rpy="0 0 0" />
          <parent link="link_caster_axis_support"/>
          <child link="link_caster_wheel"/>          
          <axis rpy="0 0 0" xyz="1 0 0"/>
          <limit effort="10000" velocity="1000"/>
          <joint_properties damping="0.80" friction="1.0"/>
    </joint>

    <joint name="joint_caster2" type="continuous">
          <origin xyz="0 0 0" rpy="0 0 0"/>
          <parent link="link_caster_base"/>
          <child link="link_caster_axis_support"/>
          <axis rpy="0 0 0" xyz="0 0 1"/>
          <limit effort="10000" velocity="1000"/>
          <joint_properties damping="0.80" friction="1.0"/>
    </joint>


    <joint name="joint_wheel_right" type="continuous">
          <origin rpy="0 0 0" xyz="0.122 0.085 0.023"/>
          <child link="link_wheel_right"/>
          <parent link="link_chassis"/>
          <axis rpy="0 0 0" xyz="-1 0 0"/>
          <limit effort="10000" velocity="1000"/>
          <joint_properties damping="0.80" friction="1.0"/>
    </joint>
    
    <joint name="joint_wheel_left" type="continuous">
          <origin rpy="0 0 0" xyz="-0.122 0.085 0.023"/>
          <child link="link_wheel_left"/>
          <parent link="link_chassis"/>
          <axis rpy="0 0 0" xyz="-1 0 0"/>
          <limit effort="10000" velocity="1000"/>
          <joint_properties damping="0.80" friction="1.0"/>
    </joint>

    <joint name="joint_imu" type="fixed">
          <origin rpy="0 0 0" xyz="0 0.085 0.02"/>
          <child link="imu_link"/>
          <parent link="link_chassis"/>
    </joint>

    <joint name="joint_camera" type="fixed">
          <origin rpy="0 0 1.57" xyz="0 0.155 0.130"/>
          <parent link="link_chassis"/>
          <child link="camera_link"/>
    </joint>

    <joint name="joint_module_jetson" type="fixed">
      <origin xyz="0.0 0.0735 0.13" rpy="0.0 0.0 0.0"/>
      <parent link="link_chassis"/>
      <child link="module_jetson_link"/>
    </joint>

    <joint name="joint_lidar" type="fixed">
          <origin rpy="0 0 1.5707" xyz="0 0.075 0.190"/>
          <parent link="link_chassis"/>
          <child link="lidar_link"/>
    </joint>

    <joint name="joint_sonar_front" type="fixed">
      <origin xyz="0 0.158 0.051" rpy="0 0 1.5707"/>
      <parent link="link_chassis"/>
      <child link="sonar_front_link"/>
    </joint>

    <joint name="joint_sonar_left" type="fixed">
      <origin xyz="-0.08 0.1405 0.051" rpy="0 0 2.1"/>
      <parent link="link_chassis"/>
      <child link="sonar_left_link"/>
    </joint>

    <joint name="joint_sonar_right" type="fixed">
      <origin xyz="0.08 0.1405 0.051" rpy="0 0 1.04"/>
      <parent link="link_chassis"/>
      <child link="sonar_right_link"/>
    </joint>
    
    <!--Transmission -->
    <transmission name="trans1">
      <type>transmission_interface/SimpleTransmission</type>
      <joint name="joint_wheel_right">
        <hardwareInterface>hardware_interface/VelocityJointInterface</hardwareInterface>
      </joint>
      <actuator name="motor1">
        <!--<hardwareInterface>hardware_interface/VelocityJointInterface</hardwareInterface>-->
        <mechanicalReduction>1</mechanicalReduction>
      </actuator>
    </transmission>

    <transmission name="trans2">
      <type>transmission_interface/SimpleTransmission</type>
      <joint name="joint_wheel_left">
        <hardwareInterface>hardware_interface/VelocityJointInterface</hardwareInterface>
      </joint>
      <actuator name="motor2">
        <!--<hardwareInterface>hardware_interface/VelocityJointInterface</hardwareInterface>-->
        <mechanicalReduction>1</mechanicalReduction>
      </actuator>
    </transmission>
    
    
</robot>